Workbook

Sheet 발사데이터
A1: 발사일 | B1: 위성명 | C1: 발사체 | D1: 총질량_kg | E1: 건조질량_kg | F1: 발사연도 | G1: 상태 | H1: 국가_운용 | I1: 궤도투입방식 | J1: 질량신뢰도 | K1: 비고
A2: 2024-01-03 | B2: Ovzon 3 | C2: Falcon 9 Block 5 | D2: 1500 | F2: 2024 | G2: 발사완료 | H2: 스웨덴 (Ovzon) | I2: GTO | J2: 추정 | K2: SSL-500 Legion class
A3: 2024-02-17 | B3: INSAT-3DS | C3: GSLV-F14 (Mk II) | D3: 2274 | E3: 907 | F3: 2024 | G3: 발사완료 | H3: 인도 (ISRO/MoES) | I3: GTO | J3: 공표 | K3: 기상
A4: 2024-03-30 | B4: Eutelsat 36D | C4: Falcon 9 Block 5 | D4: 5000 | F4: 2024 | G4: 발사완료 | H4: 프랑스 (Eutelsat) | I4: GTO | J4: 추정 | K4: Eurostar-Neo, 36E
A5: 2024-04-09 | B5: NROL-70 | C5: Delta IV Heavy | F5: 2024 | G5: 발사완료 | H5: 미국 (NRO) | I5: GEO직접 | J5: 미상 | K5: Delta IV Heavy 최종비행. ORION계열 SIGINT 추정
A6: 2024-06-20 | B6: Astra 1P / SES-24 | C6: Falcon 9 Block 5 | D6: 5000 | E6: 3780 | F6: 2024 | G6: 발사완료 | H6: 룩셈부르크 (SES) | I6: GTO | J6: 추정 | K6: Spacebus NEO-200, 19.2E
A7: 2024-06-25 | B7: GOES-U (→GOES-19) | C7: Falcon Heavy | D7: 5192 | F7: 2024 | G7: 발사완료 | H7: 미국 (NOAA) | I7: GTO | J7: 공표 | K7: 기상
A8: 2024-07-08 | B8: Turksat 6A | C8: Falcon 9 Block 5 | D8: 4250 | F8: 2024 | G8: 발사완료 | H8: 튀르키예 (Turksat) | I8: GTO | J8: 공표 | K8: 튀르키예 첫 국산 GEO, 42E
A9: 2024-07-30 | B9: USSF-51 | C9: Atlas V 551 | F9: 2024 | G9: 발사완료 | H9: 미국 (USSF) | I9: GEO직접 | J9: 미상 | K9: 기밀, GEO 3기 추정
A10: 2024-11-04 | B10: Kirameki-3 (DSN-3) | C10: H3-22S | F10: 2024 | G10: 발사완료 | H10: 일본 (방위성) | I10: GTO | J10: 미상 | K10: DS2000 버스, X밴드 군통신, 144E
A11: 2024-11-11 | B11: Koreasat 6A | C11: Falcon 9 Block 5 | D11: 3500 | F11: 2024 | G11: 발사완료 | H11: 한국 (KT SAT) | I11: GTO | J11: 공표 | K11: Spacebus-4000B2, 116E
A12: 2024-11-17 | B12: Optus-X / TD7 | C12: Falcon 9 Block 5 | F12: 2024 | G12: 발사완료 | H12: 호주 (Optus) | I12: GTO | J12: 미상 | K12: 임무 미공개
A13: 2024-11-18 | B13: GSAT-N2 (GSAT-20) | C13: Falcon 9 Block 5 | D13: 4700 | F13: 2024 | G13: 발사완료 | H13: 인도 (NSIL/ISRO) | I13: GTO | J13: 공표 | K13: I-3K, 68E
A14: 2024-12-05 | B14: SXM-9 | C14: Falcon 9 Block 5 | D14: 7000 | F14: 2024 | G14: 발사완료 | H14: 미국 (SiriusXM) | I14: GTO | J14: 추정 | K14: SSL-1300
A15: 2024-12-29 | B15: UtilitySat | C15: Falcon 9 Block 5 | D15: 400 | F15: 2024 | G15: 발사완료 | H15: 미국 (Astranis) | I15: GTO | J15: 추정 | K15: MicroGEO, 1회 4기 동시발사
A16: 2024-12-29 | B16: NuView Alpha (AstranisAero West) | C16: Falcon 9 Block 5 | D16: 400 | F16: 2024 | G16: 발사완료 | H16: 미국 (Anuvu) | I16: GTO | J16: 추정 | K16: MicroGEO
A17: 2024-12-29 | B17: NuView Bravo (AstranisAero East) | C17: Falcon 9 Block 5 | D17: 400 | F17: 2024 | G17: 발사완료 | H17: 미국 (Anuvu) | I17: GTO | J17: 추정 | K17: MicroGEO
A18: 2024-12-29 | B18: Agila (Philippines Sat 2) | C18: Falcon 9 Block 5 | D18: 400 | F18: 2024 | G18: 발사완료 | H18: 필리핀 (Orbits Corp) | I18: GTO | J18: 추정 | K18: MicroGEO, 152.1E
A19: 2025-01-04 | B19: Thuraya 4-NGS | C19: Falcon 9 Block 5 | D19: 5000 | F19: 2025 | G19: 발사완료 | H19: UAE (Space42) | I19: GTO | J19: 추정 | K19: Eurostar-Neo 전전기추진 (GEO 도달 수개월)
A20: 2025-01-29 | B20: NVS-02 | C20: GSLV-F15 | D20: 2250 | F20: 2025 | G20: 발사완료 | H20: 인도 (ISRO) | I20: GTO | J20: 공표 | K20: NavIC. 궤도상승 이상으로 목표 경사GSO 미도달
A21: 2025-01-30 | B21: Spainsat NG I | C21: Falcon 9 (소모형) | D21: 6100 | F21: 2025 | G21: 발사완료 | H21: 스페인 (Hisdesat) | I21: 고에너지 GTO | J21: 공표 | K21: Eurostar-Neo, 30W
A22: 2025-02-02 | B22: QZS-6 (Michibiki-6) | C22: H3-22S | D22: 4800 | E22: 2000 | F22: 2025 | G22: 발사완료 | H22: 일본 (내각부) | I22: GTO | J22: 공표 | K22: QZSS 정지궤도기, 90.5E
A23: 2025-06-07 | B23: SXM-10 | C23: Falcon 9 Block 5 | D23: 6400 | F23: 2025 | G23: 발사완료 | H23: 미국 (SiriusXM) | I23: GTO | J23: 공표 | K23: Maxar 1300
A24: 2025-07-01 | B24: MTG-S1 / Sentinel-4 | C24: Falcon 9 Block 5 | D24: 3800 | F24: 2025 | G24: 발사완료 | H24: EU (EUMETSAT/ESA) | I24: GTO | J24: 공표 | K24: 기상 사운더
A25: 2025-07-13 | B25: Dror 1 | C25: Falcon 9 | D25: 4000 | F25: 2025 | G25: 발사완료 | H25: 이스라엘 (정부) | I25: GTO | J25: 추정 | K25: IAI AMOS-HP 계열
A26: 2025-08-13 | B26: NTS-3 (USSF-106) | C26: Vulcan Centaur VC4S | D26: 1250 | F26: 2025 | G26: 발사완료 | H26: 미국 (USSF) | I26: GEO직접 | J26: 추정 | K26: PNT 실증. Centaur V 직접투입
A27: 2025-08-13 | B27: USA-554 (USSF-106 부수탑재) | C27: Vulcan Centaur VC4S | F27: 2025 | G27: 발사완료 | H27: 미국 (USSF) | I27: GEO직접 | J27: 미상 | K27: 기밀
A28: 2025-09-12 | B28: Nusantara Lima | C28: Falcon 9 Block 5 | D28: 7800 | F28: 2025 | G28: 발사완료 | H28: 인도네시아 (PSN) | I28: GTO | J28: 공표 | K28: Boeing 702MP. Falcon 9 GTO 최대질량 기록
A29: 2025-10-24 | B29: Spainsat NG II | C29: Falcon 9 (소모형) | D29: 6100 | F29: 2025 | G29: 발사완료 | H29: 스페인 (Hisdesat) | I29: 고에너지 GTO | J29: 공표 | K29: Eurostar-Neo, 29E
A30: 2025-11-02 | B30: CMS-03 (GSAT-7R) | C30: LVM3-M5 | D30: 4410 | F30: 2025 | G30: 발사완료 | H30: 인도 (해군) | I30: 준정지천이 (170x29970km) | J30: 공표 | K30: LVM3 최중량 GTO 페이로드
A31: 2025-11-14 | B31: ViaSat-3 F2 (EMEA) | C31: Atlas V 551 | D31: 6400 | F31: 2025 | G31: 발사완료 | H31: 미국 (Viasat) | I31: GTO | J31: 추정 | K31: BSS-702MP+
A32: 2026-02-12 | B32: GSSAP 7 (Hornet 7, USA 582) | C32: Vulcan Centaur VC4S | F32: 2026 | G32: 발사완료 | H32: 미국 (USSF) | I32: GEO직접 | J32: 미상 | K32: USSF-87. 정지궤도 상황인식(SSA)
A33: 2026-02-12 | B33: GSSAP 8 (Hornet 8, USA 583) | C33: Vulcan Centaur VC4S | F33: 2026 | G33: 발사완료 | H33: 미국 (USSF) | I33: GEO직접 | J33: 미상 | K33: USSF-87
A34: 2026-02-12 | B34: USA 584 | C34: Vulcan Centaur VC4S | F34: 2026 | G34: 발사완료 | H34: 미국 (USSF) | I34: GEO직접 | J34: 미상 | K34: USSF-87 부수탑재, 기밀
A35: 2026-02-12 | B35: Jam-e Jam 1 | C35: Proton-M Blok-DM-03 | F35: 2026 | G35: 발사완료 | H35: 이란 (정부) | I35: GTO | J35: 미상 | K35: 러시아 제작·발사, 운용주체는 이란. Elektro-L 5와 동반발사
A36: 2026-03-10 | B36: EchoStar 25 (EchoStar XXV) | C36: Falcon 9 Block 5 | D36: 6800 | F36: 2026 | G36: 발사완료 | H36: 미국 (EchoStar) | I36: GTO | J36: 공표 | K36: SSL-1300. 부스터 B1085
A37: 2026-04-29 | B37: ViaSat-3 F3 (APAC) | C37: (미확인) | D37: 6000 | F37: 2026 | G37: 발사완료 | H37: 미국 (Viasat) | I37: GTO | J37: 추정 | K37: BSS-702MP+. 발사체 미확인
A38: 2026-06-29 | B38: SXM-11 | C38: (미확인) | D38: 7000 | F38: 2026 | G38: 발사완료 | H38: 미국 (SiriusXM) | I38: GTO | J38: 추정 | K38: SSL-1300. 발사체 미확인
A39: 2026-07-21 | B39: MRV (Mission Robotic Vehicle) | C39: Falcon 9 Block 5 | F39: 2026 | G39: 발사완료 | H39: 미국 (Northrop Grumman/DARPA) | I39: GTO | J39: 미상 | K39: RSGS 궤도상 서비싱. GEO 도달까지 약 1년. B1069 소모
A40: 2026-07-21 | B40: MEP 1-3 (Mission Extension Pod x3) | C40: Falcon 9 Block 5 | F40: 2026 | G40: 발사완료 | H40: 미국 (Northrop Grumman) | I40: GTO | J40: 미상 | K40: MRV와 동반발사. Optus/SES 위성 수명연장용
...

Sheet 연도별집계
A1: 연도별 GEO 투입 집계
A2: 모든 값은 '발사데이터' 시트를 참조하는 수식입니다. 원본 시트를 수정하면 자동 갱신됩니다.
A4: 발사연도 | B4: 발사완료 (기) | C4: 발사예정 (기) | D4: 합계 (기) | E4: 질량합계 (kg, 확인분만) | F4: 질량 미상 (기) | G4: 평균질량 (kg, 확인분)
A5: 2024 | B5: =COUNTIFS(발사데이터!$F$2:$F$87,$A5,발사데이터!$G$2:$G$87,"발사완료") -> 17 | C5: =COUNTIFS(발사데이터!$F$2:$F$87,$A5,발사데이터!$G$2:$G$87,"발사예정") -> 0 | D5: =B5+C5 -> 17 | E5: =SUMIFS(발사데이터!$D$2:$D$87,발사데이터!$F$2:$F$87,$A5) -> 40016 | F5: =COUNTIFS(발사데이터!$F$2:$F$87,$A5,발사데이터!$J$2:$J$87,"미상") -> 4 | G5: =IFERROR(E5/(D5-F5),0) -> 3078.1538
A6: 2025 | B6: =COUNTIFS(발사데이터!$F$2:$F$87,$A6,발사데이터!$G$2:$G$87,"발사완료") -> 13 | C6: =COUNTIFS(발사데이터!$F$2:$F$87,$A6,발사데이터!$G$2:$G$87,"발사예정") -> 0 | D6: =B6+C6 -> 13 | E6: =SUMIFS(발사데이터!$D$2:$D$87,발사데이터!$F$2:$F$87,$A6) -> 58310 | F6: =COUNTIFS(발사데이터!$F$2:$F$87,$A6,발사데이터!$J$2:$J$87,"미상") -> 1 | G6: =IFERROR(E6/(D6-F6),0) -> 4859.1667
A7: 2026 | B7: =COUNTIFS(발사데이터!$F$2:$F$87,$A7,발사데이터!$G$2:$G$87,"발사완료") -> 9 | C7: =COUNTIFS(발사데이터!$F$2:$F$87,$A7,발사데이터!$G$2:$G$87,"발사예정") -> 14 | D7: =B7+C7 -> 23 | E7: =SUMIFS(발사데이터!$D$2:$D$87,발사데이터!$F$2:$F$87,$A7) -> 24800 | F7: =COUNTIFS(발사데이터!$F$2:$F$87,$A7,발사데이터!$J$2:$J$87,"미상") -> 14 | G7: =IFERROR(E7/(D7-F7),0) -> 2755.5556
A8: 2027 | B8: =COUNTIFS(발사데이터!$F$2:$F$87,$A8,발사데이터!$G$2:$G$87,"발사완료") -> 0 | C8: =COUNTIFS(발사데이터!$F$2:$F$87,$A8,발사데이터!$G$2:$G$87,"발사예정") -> 13 | D8: =B8+C8 -> 13 | E8: =SUMIFS(발사데이터!$D$2:$D$87,발사데이터!$F$2:$F$87,$A8) -> 11000 | F8: =COUNTIFS(발사데이터!$F$2:$F$87,$A8,발사데이터!$J$2:$J$87,"미상") -> 11 | G8: =IFERROR(E8/(D8-F8),0) -> 5500
A9: 2028 | B9: =COUNTIFS(발사데이터!$F$2:$F$87,$A9,발사데이터!$G$2:$G$87,"발사완료") -> 0 | C9: =COUNTIFS(발사데이터!$F$2:$F$87,$A9,발사데이터!$G$2:$G$87,"발사예정") -> 1 | D9: =B9+C9 -> 1 | E9: =SUMIFS(발사데이터!$D$2:$D$87,발사데이터!$F$2:$F$87,$A9) -> 0 | F9: =COUNTIFS(발사데이터!$F$2:$F$87,$A9,발사데이터!$J$2:$J$87,"미상") -> 1 | G9: =IFERROR(E9/(D9-F9),0) -> 0
A10: 2029 | B10: =COUNTIFS(발사데이터!$F$2:$F$87,$A10,발사데이터!$G$2:$G$87,"발사완료") -> 0 | C10: =COUNTIFS(발사데이터!$F$2:$F$87,$A10,발사데이터!$G$2:$G$87,"발사예정") -> 2 | D10: =B10+C10 -> 2 | E10: =SUMIFS(발사데이터!$D$2:$D$87,발사데이터!$F$2:$F$87,$A10) -> 12000 | F10: =COUNTIFS(발사데이터!$F$2:$F$87,$A10,발사데이터!$J$2:$J$87,"미상") -> 0 | G10: =IFERROR(E10/(D10-F10),0) -> 6000
A11: 2030 | B11: =COUNTIFS(발사데이터!$F$2:$F$87,$A11,발사데이터!$G$2:$G$87,"발사완료") -> 0 | C11: =COUNTIFS(발사데이터!$F$2:$F$87,$A11,발사데이터!$G$2:$G$87,"발사예정") -> 2 | D11: =B11+C11 -> 2 | E11: =SUMIFS(발사데이터!$D$2:$D$87,발사데이터!$F$2:$F$87,$A11) -> 6100 | F11: =COUNTIFS(발사데이터!$F$2:$F$87,$A11,발사데이터!$J$2:$J$87,"미상") -> 1 | G11: =IFERROR(E11/(D11-F11),0) -> 6100
A12: 2031 | B12: =COUNTIFS(발사데이터!$F$2:$F$87,$A12,발사데이터!$G$2:$G$87,"발사완료") -> 0 | C12: =COUNTIFS(발사데이터!$F$2:$F$87,$A12,발사데이터!$G$2:$G$87,"발사예정") -> 1 | D12: =B12+C12 -> 1 | E12: =SUMIFS(발사데이터!$D$2:$D$87,발사데이터!$F$2:$F$87,$A12) -> 0 | F12: =COUNTIFS(발사데이터!$F$2:$F$87,$A12,발사데이터!$J$2:$J$87,"미상") -> 1 | G12: =IFERROR(E12/(D12-F12),0) -> 0
A13: 2032 | B13: =COUNTIFS(발사데이터!$F$2:$F$87,$A13,발사데이터!$G$2:$G$87,"발사완료") -> 0 | C13: =COUNTIFS(발사데이터!$F$2:$F$87,$A13,발사데이터!$G$2:$G$87,"발사예정") -> 1 | D13: =B13+C13 -> 1 | E13: =SUMIFS(발사데이터!$D$2:$D$87,발사데이터!$F$2:$F$87,$A13) -> 0 | F13: =COUNTIFS(발사데이터!$F$2:$F$87,$A13,발사데이터!$J$2:$J$87,"미상") -> 1 | G13: =IFERROR(E13/(D13-F13),0) -> 0
A14: 9999 | B14: =COUNTIFS(발사데이터!$F$2:$F$87,$A14,발사데이터!$G$2:$G$87,"발사완료") -> 0 | C14: =COUNTIFS(발사데이터!$F$2:$F$87,$A14,발사데이터!$G$2:$G$87,"발사예정") -> 13 | D14: =B14+C14 -> 13 | E14: =SUMIFS(발사데이터!$D$2:$D$87,발사데이터!$F$2:$F$87,$A14) -> 12400 | F14: =COUNTIFS(발사데이터!$F$2:$F$87,$A14,발사데이터!$J$2:$J$87,"미상") -> 9 | G14: =IFERROR(E14/(D14-F14),0) -> 3100
A15: 합계 | B15: =B5+B6+B7+B8+B9+B10+B11+B12+B13+B14 -> 39 | C15: =C5+C6+C7+C8+C9+C10+C11+C12+C13+C14 -> 47 | D15: =D5+D6+D7+D8+D9+D10+D11+D12+D13+D14 -> 86 | E15: =E5+E6+E7+E8+E9+E10+E11+E12+E13+E14 -> 164626 | F15: =F5+F6+F7+F8+F9+F10+F11+F12+F13+F14 -> 43 | G15: =IFERROR(E15/(D15-F15),0) -> 3828.5116
A17: * 발사연도 9999 = 발주는 됐으나 발사시기 미정(Gunter's 표기 '202x')
A18: * '질량합계'는 총질량이 알려진 위성만 더한 값입니다. 미상 위성이 많은 연도는 과소집계됩니다.

Sheet README
A1: GEO 투입 위성 데이터셋 (2024 - 2026 및 이후 발사예정) — 중국·러시아 제외
A3: ■ 수록 범위
A4: GEO를 최종 목적지로 하는 위성 (GTO / GEO 직접투입 / 준정지천이권도 포함).
A5: 운용주체 기준으로 중국·러시아 위성은 전부 제외했습니다.
A6: 단, Jam-e Jam 1은 러시아가 제작·발사했지만 운용주체가 이란이라 포함됐습니다.
A7: MEO(GPS, Galileo, O3b 등), HEO/몰니야(ASBM 등), LEO는 제외했습니다.
A9: ■ 컬럼 설명
A10: 발사일 : 실제 발사일(UTC). 발사예정 건은 대부분 공란 — '발사연도'만 채워져 있습니다.
A11: 총질량_kg : 발사질량(launch mass, 추진제 포함). 파란색 = 외부 출처에서 가져온 입력값.
A12: 건조질량_kg : dry mass. 공개된 경우만 기재 — 대부분 공란입니다.
A13: 질량신뢰도 : 공표(운용사/제조사 발표) / 추정(버스 계열 기반) / 미상.
A14: 권도투입방식 : GTO / 고에너지 GTO / GEO직접 / 준정지천이 / 미상. 델타-V 모델링용.
... A36: satsig.net GEO 목록, orbitalfocus.uk Geosynchronous Satellites.
